<?xml version="1.0"?>
<robot name="simple_humanoid">

  <!-- Torso -->
  <link name="torso">
    <visual>
      <origin xyz="0 0 0.5" rpy="0 0 0"/>
      <geometry>
        <box size="0.3 0.3 1.0"/>
      </geometry>
      <material name="white">
        <color rgba="1 1 1 1"/>
      </material>
    </visual>
    <collision>
      <origin xyz="0 0 0.5" rpy="0 0 0"/>
      <geometry>
        <box size="0.3 0.3 1.0"/>
      </geometry>
    </collision>
    <inertial>
      <mass value="10.0"/>
      <origin xyz="0 0 0.5" rpy="0 0 0"/>
      <inertia ixx="0.225" ixy="0.0" ixz="0.0" iyy="0.225" iyz="0.0" izz="0.15"/>
    </inertial>
  </link>

  <!-- Head -->
  <link name="head">
    <visual>
      <origin xyz="0 0 0" rpy="0 0 0"/>
      <geometry>
        <sphere radius="0.15"/>
      </geometry>
      <material name="skin">
        <color rgba="0.8 0.6 0.4 1"/>
      </material>
    </visual>
    <collision>
      <origin xyz="0 0 0" rpy="0 0 0"/>
      <geometry>
        <sphere radius="0.15"/>
      </geometry>
    </collision>
    <inertial>
      <mass value="2.0"/>
      <origin xyz="0 0 0" rpy="0 0 0"/>
      <inertia ixx="0.015" ixy="0.0" ixz="0.0" iyy="0.015" iyz="0.0" izz="0.015"/>
    </inertial>
  </link>

  <!-- Neck Joint -->
  <joint name="neck_joint" type="revolute">
    <parent link="torso"/>
    <child link="head"/>
    <origin xyz="0 0 1.0" rpy="0 0 0"/>
    <axis xyz="0 1 0"/>
    <limit lower="-0.5" upper="0.5" effort="50.0" velocity="1.0"/>
  </joint>

  <!-- Left Arm -->
  <link name="left_upper_arm">
    <visual>
      <origin xyz="0 0 -0.15" rpy="1.57079632679 0 0"/>
      <geometry>
        <cylinder length="0.3" radius="0.05"/>
      </geometry>
      <material name="arm_color">
        <color rgba="0.6 0.8 1.0 1"/>
      </material>
    </visual>
    <collision>
      <origin xyz="0 0 -0.15" rpy="1.57079632679 0 0"/>
      <geometry>
        <cylinder length="0.3" radius="0.05"/>
      </geometry>
    </collision>
    <inertial>
      <mass value="1.0"/>
      <origin xyz="0 0 -0.15" rpy="1.57079632679 0 0"/>
      <inertia ixx="0.005" ixy="0.0" ixz="0.0" iyy="0.005" iyz="0.0" izz="0.0025"/>
    </inertial>
  </link>

  <link name="left_lower_arm">
    <visual>
      <origin xyz="0 0 -0.15" rpy="1.57079632679 0 0"/>
      <geometry>
        <cylinder length="0.3" radius="0.04"/>
      </geometry>
      <material name="arm_color">
        <color rgba="0.6 0.8 1.0 1"/>
      </material>
    </visual>
    <collision>
      <origin xyz="0 0 -0.15" rpy="1.57079632679 0 0"/>
      <geometry>
        <cylinder length="0.3" radius="0.04"/>
      </geometry>
    </collision>
    <inertial>
      <mass value="0.8"/>
      <origin xyz="0 0 -0.15" rpy="1.57079632679 0 0"/>
      <inertia ixx="0.004" ixy="0.0" ixz="0.0" iyy="0.004" iyz="0.0" izz="0.002"/>
    </inertial>
  </link>

  <!-- Left Shoulder Joint -->
  <joint name="left_shoulder_joint" type="revolute">
    <parent link="torso"/>
    <child link="left_upper_arm"/>
    <origin xyz="0.25 0 0.8" rpy="0 0 0"/>
    <axis xyz="0 1 0"/>
    <limit lower="-1.57" upper="1.57" effort="50.0" velocity="1.0"/>
  </joint>

  <!-- Left Elbow Joint -->
  <joint name="left_elbow_joint" type="revolute">
    <parent link="left_upper_arm"/>
    <child link="left_lower_arm"/>
    <origin xyz="0 0 -0.3" rpy="0 0 0"/>
    <axis xyz="0 1 0"/>
    <limit lower="-1.57" upper="1.57" effort="30.0" velocity="1.0"/>
  </joint>

  <!-- Right Arm (similar to left) -->
  <link name="right_upper_arm">
    <visual>
      <origin xyz="0 0 -0.15" rpy="1.57079632679 0 0"/>
      <geometry>
        <cylinder length="0.3" radius="0.05"/>
      </geometry>
      <material name="arm_color">
        <color rgba="0.6 0.8 1.0 1"/>
      </material>
    </visual>
    <collision>
      <origin xyz="0 0 -0.15" rpy="1.57079632679 0 0"/>
      <geometry>
        <cylinder length="0.3" radius="0.05"/>
      </geometry>
    </collision>
    <inertial>
      <mass value="1.0"/>
      <origin xyz="0 0 -0.15" rpy="1.57079632679 0 0"/>
      <inertia ixx="0.005" ixy="0.0" ixz="0.0" iyy="0.005" iyz="0.0" izz="0.0025"/>
    </inertial>
  </link>

  <link name="right_lower_arm">
    <visual>
      <origin xyz="0 0 -0.15" rpy="1.57079632679 0 0"/>
      <geometry>
        <cylinder length="0.3" radius="0.04"/>
      </geometry>
      <material name="arm_color">
        <color rgba="0.6 0.8 1.0 1"/>
      </material>
    </visual>
    <collision>
      <origin xyz="0 0 -0.15" rpy="1.57079632679 0 0"/>
      <geometry>
        <cylinder length="0.3" radius="0.04"/>
      </geometry>
    </collision>
    <inertial>
      <mass value="0.8"/>
      <origin xyz="0 0 -0.15" rpy="1.57079632679 0 0"/>
      <inertia ixx="0.004" ixy="0.0" ixz="0.0" iyy="0.004" iyz="0.0" izz="0.002"/>
    </inertial>
  </link>

  <!-- Right Shoulder Joint -->
  <joint name="right_shoulder_joint" type="revolute">
    <parent link="torso"/>
    <child link="right_upper_arm"/>
    <origin xyz="-0.25 0 0.8" rpy="0 0 0"/>
    <axis xyz="0 1 0"/>
    <limit lower="-1.57" upper="1.57" effort="50.0" velocity="1.0"/>
  </joint>

  <!-- Right Elbow Joint -->
  <joint name="right_elbow_joint" type="revolute">
    <parent link="right_upper_arm"/>
    <child link="right_lower_arm"/>
    <origin xyz="0 0 -0.3" rpy="0 0 0"/>
    <axis xyz="0 1 0"/>
    <limit lower="-1.57" upper="1.57" effort="30.0" velocity="1.0"/>
  </joint>

  <!-- Left Leg -->
  <link name="left_upper_leg">
    <visual>
      <origin xyz="0 0 -0.25" rpy="1.57079632679 0 0"/>
      <geometry>
        <cylinder length="0.5" radius="0.06"/>
      </geometry>
      <material name="leg_color">
        <color rgba="0.5 0.5 0.5 1"/>
      </material>
    </visual>
    <collision>
      <origin xyz="0 0 -0.25" rpy="1.57079632679 0 0"/>
      <geometry>
        <cylinder length="0.5" radius="0.06"/>
      </geometry>
    </collision>
    <inertial>
      <mass value="2.0"/>
      <origin xyz="0 0 -0.25" rpy="1.57079632679 0 0"/>
      <inertia ixx="0.04" ixy="0.0" ixz="0.0" iyy="0.04" iyz="0.0" izz="0.01"/>
    </inertial>
  </link>

  <link name="left_lower_leg">
    <visual>
      <origin xyz="0 0 -0.25" rpy="1.57079632679 0 0"/>
      <geometry>
        <cylinder length="0.5" radius="0.05"/>
      </geometry>
      <material name="leg_color">
        <color rgba="0.5 0.5 0.5 1"/>
      </material>
    </visual>
    <collision>
      <origin xyz="0 0 -0.25" rpy="1.57079632679 0 0"/>
      <geometry>
        <cylinder length="0.5" radius="0.05"/>
      </geometry>
    </collision>
    <inertial>
      <mass value="1.5"/>
      <origin xyz="0 0 -0.25" rpy="1.57079632679 0 0"/>
      <inertia ixx="0.03" ixy="0.0" ixz="0.0" iyy="0.03" iyz="0.0" izz="0.008"/>
    </inertial>
  </link>

  <!-- Left Hip Joint -->
  <joint name="left_hip_joint" type="revolute">
    <parent link="torso"/>
    <child link="left_upper_leg"/>
    <origin xyz="0.12 0 0" rpy="0 0 0"/>
    <axis xyz="0 1 0"/>
    <limit lower="-1.57" upper="1.57" effort="100.0" velocity="1.0"/>
  </joint>

  <!-- Left Knee Joint -->
  <joint name="left_knee_joint" type="revolute">
    <parent link="left_upper_leg"/>
    <child link="left_lower_leg"/>
    <origin xyz="0 0 -0.5" rpy="0 0 0"/>
    <axis xyz="0 1 0"/>
    <limit lower="0" upper="1.57" effort="80.0" velocity="1.0"/>
  </joint>

  <!-- Right Leg -->
  <link name="right_upper_leg">
    <visual>
      <origin xyz="0 0 -0.25" rpy="1.57079632679 0 0"/>
      <geometry>
        <cylinder length="0.5" radius="0.06"/>
      </geometry>
      <material name="leg_color">
        <color rgba="0.5 0.5 0.5 1"/>
      </material>
    </visual>
    <collision>
      <origin xyz="0 0 -0.25" rpy="1.57079632679 0 0"/>
      <geometry>
        <cylinder length="0.5" radius="0.06"/>
      </geometry>
    </collision>
    <inertial>
      <mass value="2.0"/>
      <origin xyz="0 0 -0.25" rpy="1.57079632679 0 0"/>
      <inertia ixx="0.04" ixy="0.0" ixz="0.0" iyy="0.04" iyz="0.0" izz="0.01"/>
    </inertial>
  </link>

  <link name="right_lower_leg">
    <visual>
      <origin xyz="0 0 -0.25" rpy="1.57079632679 0 0"/>
      <geometry>
        <cylinder length="0.5" radius="0.05"/>
      </geometry>
      <material name="leg_color">
        <color rgba="0.5 0.5 0.5 1"/>
      </material>
    </visual>
    <collision>
      <origin xyz="0 0 -0.25" rpy="1.57079632679 0 0"/>
      <geometry>
        <cylinder length="0.5" radius="0.05"/>
      </geometry>
    </collision>
    <inertial>
      <mass value="1.5"/>
      <origin xyz="0 0 -0.25" rpy="1.57079632679 0 0"/>
      <inertia ixx="0.03" ixy="0.0" ixz="0.0" iyy="0.03" iyz="0.0" izz="0.008"/>
    </inertial>
  </link>

  <!-- Right Hip Joint -->
  <joint name="right_hip_joint" type="revolute">
    <parent link="torso"/>
    <child link="right_upper_leg"/>
    <origin xyz="-0.12 0 0" rpy="0 0 0"/>
    <axis xyz="0 1 0"/>
    <limit lower="-1.57" upper="1.57" effort="100.0" velocity="1.0"/>
  </joint>

  <!-- Right Knee Joint -->
  <joint name="right_knee_joint" type="revolute">
    <parent link="right_upper_leg"/>
    <child link="right_lower_leg"/>
    <origin xyz="0 0 -0.5" rpy="0 0 0"/>
    <axis xyz="0 1 0"/>
    <limit lower="0" upper="1.57" effort="80.0" velocity="1.0"/>
  </joint>
</robot>